Workbook

Sheet 最新价格
A1: 抓取时间 | B1: 游戏名 | C1: 版本 | D1: 商品标题 | E1: 价格 | F1: 卖家 | G1: 地区 | H1: 商品链接 | I1: 宣传图路径 | J1: 卡带信息图路径 | K1: 商品描述 | L1: 成色
A2: 2026-07-06 21:01:36 | B2: 塞尔达传说：王国之泪 | C2: 卡带 | D2: 出闲置 Switch《塞尔达传说：王国之泪》中文卡带，几乎全 新，带原装盒，插卡即玩，正版实体卡，非偏远地区包邮，不议价，砍价不回，喜欢直接拍，细节私聊。 | E2: 230 | F2: 去码头卖点咸鱼 | G2: 上海 | H2: https://www.goofish.com/item/1065525172471
A3: 2026-07-06 21:01:36 | B3: 塞尔达传说：王国之泪 | C3: 卡带 | D3: 几乎全新Switch《塞尔达传说：王国之泪》港版中文卡带，带 原装盒子，卡带盘面干净，金手指亮，插卡即玩，支持所有Switch主机，国行也能用，中文界面，支持amiibo，联机没问题，动作冒险类，6岁以上都能玩，内容齐全，无划痕，无异常，读卡没问题，功能正常，插上就能玩，补坑收藏都合适。 同城可自提，价格好说，喜欢直接拍，细节图私聊发～ | E3: 225 | F3: 郑习惯的电玩小店 | G3: 广东 | H3: https://www.goofish.com/item/1063556538180
A4: 2026-07-06 21:01:36 | B4: 塞尔达传说：王国之泪 | C4: 卡带 | D4: 【现货直发】 塞尔达传说王国之泪典藏版含卡带港版中文 实体卡 带 | E4: 480 | F4: 高品质正品百货店 | G4: 广东 | H4: https://www.goofish.com/item/1053308770307
A5: 2026-07-06 21:01:36 | B5: 塞尔达传说：王国之泪 | C5: 卡带 | D5: Nintendo Switch 塞尔达传说：王国之泪 美版卡 带，带原包装盒，正版实体卡，插卡即玩，支持所有Switch主机（国行/港版/日版/欧美版都能用），动作冒险类，玩法自由，探索创造，amiibo兼容，聚会、朋友、家庭都适合，塞尔达系列粉丝必入～ 卡带和盒子保存很好，轻微划痕磨损，读卡正常，到手即玩！ 包邮，可自提，喜欢直接拍或私聊细节图～ 分类：Switch游戏卡带 成色：轻微划痕 | E5: 245 | F5: 新手铲屎官 | G5: 北京 | H5: https://www.goofish.com/item/1065444324578
A6: 2026-07-06 21:01:36 | B6: 塞尔达传说：王国之泪 | C6: 卡带 | D6: Switch 塞尔达传说 王国之泪 港版中文卡带 几乎全新 带原装盒 卡带读取正常 包邮非偏远 喜欢直接拍 | E6: 239 | F6: 啦啦lllllll6 | G6: 北京 | H6: https://www.goofish.com/item/1034339190197
A7: 2026-07-06 21:01:36 | B7: 塞尔达传说：王国之泪 | C7: 卡带 | D7: 【包邮】Switch 塞尔达传说 王国之泪 中文卡带 几乎全新，带原装盒，正版实体卡带，插卡即玩，支持所有Switch主机，中文界面，动作冒险经典，玩法丰富，适合喜欢塞尔达系列和冒险游戏的朋友！ 【一】24小时内发货，包邮，新疆西藏补运费 【二】游戏有中文，支持所有Switch主机 【三】带原装盒，外观保存很好 【四】放心购买，不读卡不能玩包退，来回运费我承担 【五】不玩了包回收，走闲鱼，回收有 | E7: 238 | F7: 奥尔良电玩家 | G7: 天津 | H7: https://www.goofish.com/item/1057461010835
A8: 2026-07-06 21:01:36 | B8: 塞尔达传说：王国之泪 | C8: 卡带 | D8: 几乎全新Switch《塞尔达传说：王国之泪》港版中文卡带，带 原装盒子，保存很不错，卡带盘面干净，金手指无划痕，插卡即玩，支持所有Switch主机，国行也能用，中文界面，支持amiibo，联机没问题，动作冒险经典神作，画面超美，玩法丰富，6岁以上都能玩，盒子和卡带都在，内容齐全，读卡正常，功能无异常，放心入。 同城可自提，价格好说，喜欢直接拍，细节图私聊发～ | E8: 210 | F8: 郑习惯的电玩小店 | G8: 广东 | H8: https://www.goofish.com/item/1062746051297
A9: 2026-07-06 21:01:36 | B9: 塞尔达传说：王国之泪 | C9: 卡带 | D9: Switch 塞尔达传说 王国之泪 中文卡带，插卡即玩，支持 中文，画面精美，玩法丰富，动作冒险经典，喜欢塞尔达的朋友别错过。卡带保存很好，功能正常，成色实图所拍，看准再下单，售出不退不换。非偏远地区包邮，偏远地区补差5元，售后需要提供完整开箱视频 | E9: 222 | F9: 欧洲贴地爬行的雷电水母 | G9: 广东 | H9: https://www.goofish.com/item/1065071636384
A10: 2026-07-06 21:01:36 | B10: 塞尔达传说：王国之泪 | C10: 卡带 | D10: switch 塞尔达传说 王国之泪 港版 中文卡带 几乎全新，已通关，带原装盒和卡带 支持中文，支持amiibo，所有Switch主机通用 包邮，不退不换 需要直接拍，有问题私聊 | E10: 240 | F10: 办公室骑摩托的蓝带鱼 | G10: 北京 | H10: https://www.goofish.com/item/1044177782357
A11: 2026-07-06 21:01:36 | B11: 塞尔达传说：王国之泪 | C11: 卡带 | D11: 塞尔达王国之泪 港版中文卡带，带原装盒，成色几乎全新，插卡即 玩，支持所有Switch主机，简体中文，动作冒险经典，剧情画面都很棒，适合自用或收藏，包邮 杭州临平附近可自提，喜欢直接拍，细节私聊 | E11: 240 | F11: 臭垃圾佬 | G11: 浙江 | H11: https://www.goofish.com/item/1064962448011
A12: 2026-07-06 21:01:36 | B12: 塞尔达传说：王国之泪 | C12: 卡带 | D12: switch塞尔达传说 王国之泪 中文卡带，插卡即玩，支持所 有Switch主机，日版也能用。卡带保存很好，盒子完整，功能正常，成色实图所拍，适合喜欢塞尔达系列和动作冒险游戏的朋友收藏或自用。二手卡带，功能正常，成色实图所拍，看准再下单，售出不退不换。非偏远地区包邮，偏远地区补差5元，售后需要提供完整开箱视频 | E12: 222 | F12: 欧洲贴地爬行的雷电水母 | G12: 广东 | H12: https://www.goofish.com/item/1063118754379
A13: 2026-07-06 21:01:36 | B13: 塞尔达传说：王国之泪 | C13: 卡带 | D13: 塞尔达传说王国之泪 switch实体游戏卡带 二手带盒 二手外版带盒无损，版本随机，读卡正常 已清洁消毒。 包邮非偏远地区 不管在哪买的，玩腻或者通关都支持回收 | E13: 224.8 | F13: 桃源电玩 | G13: 广东 | H13: https://www.goofish.com/item/1045929876220
... A61: 2026-07-06 21:01:36 | B61: 塞尔达传说：王国之泪 | C61: 卡带 | D61: 几乎全新Switch《塞尔达传说：王国之泪》港版中文卡带，带 原装盒，插卡即玩，支持所有Switch主机，国行/港版/日版都能用，中文界面，动作冒险神作，适合6岁以上玩家！ 卡带外观很新，盒子包装都在，盘面干净没划痕，保存得很不错，正版保证，收藏自用都合适～ 包邮！支持自提，价格可聊，喜欢直接拍，细节图私聊发～ | E61: 225 | F61: flora666h | G61: 浙江 | H61: https://www.goofish.com/item/1060500643487
A62: 2026-07-06 21:01:36 | B62: 塞尔达传说：王国之泪 | C62: 卡带 | D62: 塞尔达传说王国之泪Switch卡带任天堂Switch游戏《塞 尔达传说：王国之泪》实体卡带，支持中文，兼容所有Switch主机。卡带外观整洁，金手指无氧化，插拔顺畅，功能正常，带盒。 | E62: 230 | G62: 河南 | H62: https://www.goofish.com/item/1065168564507
A63: 2026-07-06 21:01:36 | B63: 塞尔达传说：王国之泪 | C63: 卡带 | D63: 塞尔达传说王国之泪实体卡 接近全新 中文版 可以直接拍 图为购买记录 | E63: 230 | F63: 游塵 | G63: 北京 | H63: https://www.goofish.com/item/1055647935424
A64: 2026-07-06 21:01:36 | B64: 塞尔达传说：王国之泪 | C64: 卡带 | D64: Switch《塞尔达传说 王国之泪》港版中文，仅插拔2次，几 乎全新，带原包装盒，正版实体卡带，内容完整，插卡即玩，支持所有Switch主机，动作冒险经典，可直拍 | E64: 235 | F64: 叶芽Leafbud | G64: 河北 | H64: https://www.goofish.com/item/1057493056166
A65: 2026-07-06 21:01:36 | B65: 塞尔达传说：王国之泪 | C65: 卡带 | D65: 几乎全新Switch《塞尔达传说：王国之泪》日版卡带，带原装 盒子，盘面干净，保存很不错，正版实体卡带，插卡即玩，支持所有Switch主机，动作冒险类神作，剧情丰富，开放世界探索，喜欢塞尔达系列的别错过～ 盒子和卡带都在，内容齐全，无划痕，无异常，读卡没问题，功能正常，放心入。 同城可自提，价格好说，喜欢直接拍，细节图私聊发～ | E65: 225 | F65: 郑习惯的电玩小店 | G65: 广东 | H65: https://www.goofish.com/item/1060681771343
A66: 2026-07-06 21:01:36 | B66: 塞尔达传说：王国之泪 | C66: 卡带 | D66: 个人闲置Switch《塞尔达传说：王国之泪》港版中文卡带，几 乎全新，带原装盒，保存很好，没啥明显使用痕迹。插卡即玩，支持所有Switch主机，国行、日版、港版都能用，正版保证，动作冒险类，探索乐趣多，喜欢塞尔达系列的别错过！ 不包邮，不退不换，介意勿拍。喜欢直接拍，细节图私聊发～ | E66: 230 | F66: 更努力皮皮虾蕊琪 | G66: 湖南 | H66: https://www.goofish.com/item/1064106709677
A67: 2026-07-06 21:01:36 | B67: 塞尔达传说：王国之泪 | C67: 卡带 | D67: 已下架 感兴趣的话点“我想要”和我私聊吧～ | E67: 355 | F67: 我是小烟头 | G67: 广东 | H67: https://www.goofish.com/item/1060563649975
A68: 2026-07-06 21:01:36 | B68: 塞尔达传说：王国之泪 | C68: 卡带 | D68: Switch塞尔达王国之泪 港版中文卡带，带盒，正版，插卡即 玩。 | E68: 260 | F68: 陈以根号二 | G68: 江苏 | H68: https://www.goofish.com/item/1057885576739
A69: 2026-07-06 21:01:36 | B69: 塞尔达传说：王国之泪 | C69: 卡带 | D69: 塞尔达传说王国之泪港版中文 任天堂Switch游戏《塞尔达传说：王国之泪》港版中文实体卡带，带原装盒，卡带表面干净，金手指无明显氧化，功能正常，支持所有Switch主机。 | E69: 250 | F69: 冥王星知足的荠菜 | G69: 宁夏 | H69: https://www.goofish.com/item/1046727565964
A70: 2026-07-06 21:01:36 | B70: 塞尔达传说：王国之泪 | C70: 卡带 | D70: 塞尔达传说 王国之泪 Switch港版实体卡带，中文，支持所 有Switch主机，国行/非国行都能用。带原装盒，成色几乎全新，盘面无划痕，功能正常，插卡即玩。适合喜欢开放世界动作冒险的玩家，收藏自用都合适。 温馨提示： 1、支持自提，南昌本地可约 2、售出不退不换 3、喜欢直接拍 | E70: 239 | F70: 桃桃子 | G70: 江西 | H70: https://www.goofish.com/item/1047331365265
A71: 2026-07-06 21:01:36 | B71: 塞尔达传说：王国之泪 | C71: 卡带 | D71: 99新！Switch 塞尔达传说 王国之泪 港版中文卡带，带 原装盒子，保存很好，正版卡带，插上即玩～ 支持中文 包邮，同城可自提 喜欢直接拍，细节私聊 正品保证！ 不刀！！ | E71: 250 | F71: 硬核研究所 | G71: 北京 | H71: https://www.goofish.com/item/1054763649487
A72: 2026-07-06 21:01:36 | B72: 塞尔达传说：王国之泪 | C72: 卡带 | D72: 99新 塞尔达传说王国之泪实体典藏版（无游戏卡带） 官方正品 只拆封看过 保存很新 包装有点小磨痕 喜欢直接拍 细节私聊～ | E72: 258 | F72: TianCan | G72: 广东 | H72: https://www.goofish.com/item/1054852779457
A73: 2026-07-06 21:01:36 | B73: 塞尔达传说：王国之泪 | C73: 卡带 | D73: Switch 塞尔达传说：王国之泪 自用闲置，带原装盒，卡带保存很好，只使用过两次，几乎全新 售出不退 | E73: 257 | F73: Leo电子工作室 | G73: 江苏 | H73: https://www.goofish.com/item/1039650090036
A74: 2026-07-06 21:01:36 | B74: 塞尔达传说：王国之泪 | C74: 卡带 | D74: 魂斗罗：加鲁加行动，塞尔达王国之泪，蕉力全开，马里奥赛车世界 ，都是全新未拆封 一口价，不包邮，买几张都是不砍价不包邮。 优先出打包的 | E74: 200 | F74: 泡芙喵喵? | G74: 江苏 | H74: https://www.goofish.com/item/1064506008279
... A97: 2026-07-06 21:01:36 | B97: 塞尔达传说：王国之泪 | C97: 卡带 | D97: 几乎全新Switch《塞尔达传说：王国之泪》欧版卡带，型号H AC-008 AXN7A09A000，正版实体，盘面干净，金手指状态很好，插卡即玩，支持所有Switch主机，动作冒险类，剧情丰富，玩法多样，喜欢塞尔达系列的别错过～ 只有卡带，无盒子，内容齐全，无划痕，无异常，读卡没问题，功能正常，收藏补坑都合适。 同城可自提，价格好说，喜欢直接拍，细节图私聊发～ | E97: 223 | F97: 郑习惯的电玩小店 | G97: 广东 | H97: https://www.goofish.com/item/1059602257662
A98: 2026-07-06 21:01:36 | B98: 塞尔达传说：王国之泪 | C98: 卡带 | D98: 塞尔达传说王国之泪游戏卡带 Switch平台游戏《塞尔达传说 王国之泪》实体卡带，屏幕显示游戏主界面，卡带外壳为黑色带浮雕纹饰边框，已通电可正常启动。 | E98: 75 | G98: 湖北 | H98: https://www.goofish.com/item/1049112401030
A99: 2026-07-06 21:01:36 | B99: 塞尔达传说：王国之泪 | C99: 卡带 | D99: Switch一代，塞尔达传说王国之泪游戏卡带，实体店入手，一 手自用成色充新，就玩了一次通关，闲置出，贩子勿扰，沈阳本地自提优先，外地爽快的包邮非偏远。 | E99: 238 | F99: Kevinkong_cn | G99: 辽宁 | H99: https://www.goofish.com/item/1063415093652
A100: 2026-07-06 21:01:36 | B100: 塞尔达传说：王国之泪 | C100: 卡带 | D100: 任天堂Switch 塞尔达传说 王国之泪 港版中文 几乎全新，带原装盒，卡带保存很好 正版卡带，读卡正常，插上即玩 包邮，可自提 不议价 | E100: 220 | F100: 半岛托腮的探花 | G100: 黑龙江 | H100: https://www.goofish.com/item/1064701212114
A101: 2026-07-06 21:01:36 | B101: 塞尔达传说：王国之泪 | C101: 卡带 | D101: 塞尔达传说王国之泪港版中文 任天堂Switch游戏《塞尔达传说：王国之泪》港版中文实体卡带，带原装盒，卡带外观干净，功能正常，支持所有Switch主机。 | E101: 245 | F101: 破忒头1 | G101: 四川 | H101: https://www.goofish.com/item/1049118792006
A102: 2026-07-06 21:01:36 | B102: 塞尔达传说：王国之泪 | C102: 卡带 | D102: 塞尔达传说王国之泪Switch卡带 日版《塞尔达传说：王国之泪》Switch实体游戏卡带，封面显示CERO B评级和日文标题，确认为官方正版。当前仅提供封面图，实物卡带、原包装盒、说明书及成色情况待确认。 | E102: 248 | F102: tbNick_4yfem | G102: 内蒙古 | H102: https://www.goofish.com/item/1033567399406
A103: 2026-07-06 21:01:36 | B103: 塞尔达传说：王国之泪 | C103: 卡带 | D103: 塞尔达王国之泪，Switch游戏卡带，全新日版，带原包装盒， 支持中文，插卡即玩，动作冒险开放世界，剧情超精彩！ 包邮发货，喜欢可以直接拍哦～ | E103: 277 | F103: 伊丽莎圆 | G103: 四川 | H103: https://www.goofish.com/item/1050145366617
A104: 2026-07-06 21:01:36 | B104: 塞尔达传说：王国之泪 | C104: 卡带 | D104: 塞尔达传说王国之泪 Switch卡带 成色几乎全新，带原装盒，卡带保存很好，插拔次数少，读卡正常 支持所有Switch主机，中文版，插卡即玩 包邮，可自提 喜欢的朋友可以私聊 | E104: 230 | F104: 平平安安 | G104: 天津 | H104: https://www.goofish.com/item/1057305966532
A105: 2026-07-06 21:01:36 | B105: 塞尔达传说：王国之泪 | C105: 卡带 | D105: 几乎全新 任天堂switch塞尔达王国之泪中文卡带 保存很好 没啥使用痕迹 适合喜欢塞尔达的玩家 支持自提 也可以邮寄 邮费zz 价格可聊 细节图私聊发 喜欢直接拍～ | E105: 261 | F105: 锡都理财的纸鳐 | G105: 安徽 | H105: https://www.goofish.com/item/1059236108816
A106: 2026-07-06 21:01:36 | B106: 塞尔达传说：王国之泪 | C106: 卡带 | D106: 【包邮】塞尔达传说：王国之泪 Switch卡带 日版中文，带原装盒，仅拔插过几次；插卡即玩 正版卡带，支持所有Switch主机 标价包邮 | E106: 229 | F106: 故作轻松的轻松熊 | G106: 山东 | H106: https://www.goofish.com/item/1061314722545
A107: 2026-07-06 21:01:36 | B107: 塞尔达传说：王国之泪 | C107: 卡带 | D107: Switch 塞尔达传说 王国之泪 带原装盒，不刀，包邮，售出不退不换，无售后。 | E107: 225 | F107: 渣还是那个渣 | G107: 江苏 | H107: https://www.goofish.com/item/1061980053042
A108: 2026-07-06 21:01:36 | B108: 塞尔达传说：王国之泪 | C108: 卡带 | D108: Switch《塞尔达传说：王国之泪》港版中文卡带，带原装盒， 盒子卡带都在，简体中文界面，包邮。 | E108: 221 | F108: 南风几时回 | G108: 云南 | H108: https://www.goofish.com/item/1049958130833
A109: 2026-07-06 21:01:36 | B109: 塞尔达传说：王国之泪 | C109: 卡带 | D109: ns卡带，switch游戏，塞尔达传说智慧再现港版，带原装盒 ，成色挺好，插卡即玩。同城可自提。 | E109: 200 | F109: boblue1982 | G109: 山东 | H109: https://www.goofish.com/item/1041663395055
...

Sheet 价格历史
A1: 抓取日期 | B1: 抓取时间 | C1: 游戏名 | D1: 版本 | E1: 商品ID | F1: 商品标题 | G1: 价格 | H1: 卖家 | I1: 地区 | J1: 商品链接
A2: 2026-07-06 | B2: 2026-07-06 15:13:35 | C2: 塞尔达传说：王国之泪 | D2: 卡带 | E2: 1065071636384 | F2: Switch 塞尔达传说 王国之泪 中文卡带，插卡即玩，支持 中文，画面精美，玩法丰富，动作冒险经典，喜欢塞尔达的朋友别错过。卡带保存很好，功能正常，成色实图所拍，看准再下单，售出不退不换。非偏远地区包邮，偏远地区补差5元，售后需要提供完整开箱视频 | G2: 222 | H2: 广东卖家信用极好 | J2: https://www.goofish.com/item?id=1065071636384&categoryId=201538503
A3: 2026-07-06 | B3: 2026-07-06 15:13:35 | C3: 塞尔达传说：王国之泪 | D3: 卡带 | E3: 1062436555866 | F3: 现货！任天堂Switch《塞尔达传说：王国之泪》港版中文卡带 ，支持所有Switch主机，插卡即玩。正版实体卡，带原包装盒，功能正常，成色几乎全新，保存很好，收藏自用都合适。动作冒险类，剧情丰富，画面精美，适合喜欢塞尔达系列的朋友。包邮 支持自提喜欢直接拍 细节私聊 | G3: 225 | H3: 北京卖家信用极好 | J3: https://www.goofish.com/item?id=1062436555866&categoryId=201538503
A4: 2026-07-06 | B4: 2026-07-06 15:13:35 | C4: 塞尔达传说：王国之泪 | D4: 卡带 | E4: 1063504494143 | F4: 塞尔达传说 呼吸之野 王者天下之泪 Switc 日本代购 塞尔达传说 呼吸之野 王者天下之泪 Switch【商品信息】已确认通电正常、各项功能可正常使用塞尔达传说旷野之息旷野之息（简称）王国之泪蒂亚金Nintendo Switch柔软实体版夏日开场礼上线啦！7.2-7.7 限时9折拍下后自动改价，等待改价成功后再付款哦由于海关备案规则调整，二手衣物类商品（适用范围：包含上衣、裤装、裙装、外套、童装 | G4: 512 | H4: 广东回复超快 | J4: https://www.goofish.com/item?id=1063504494143&categoryId=201538503
A5: 2026-07-06 | B5: 2026-07-06 15:13:35 | C5: 塞尔达传说：王国之泪 | D5: 卡带 | E5: 1063045721996 | F5: Switch《塞尔达传说：王国之泪》港版实体卡带 支持中文 带原包装盒正版实体卡 插卡即玩珠海现货 下午2点前付款当天发货 包邮不还价 还价勿扰售出不退 | G5: 239 | H5: 广东百分百好评 | J5: https://www.goofish.com/item?id=1063045721996&categoryId=201538503
A6: 2026-07-06 | B6: 2026-07-06 15:13:35 | C6: 塞尔达传说：王国之泪 | D6: 卡带 | E6: 1063894193418 | F6: Switch OLED游戏机贴纸 普通版/续航版贴纸塞 尔达传说王国之泪UCG特典全新未拆封，原包装在包邮非偏远喜欢直接拍，细节私聊 | H6: 江苏百分百好评 | J6: https://www.goofish.com/item?id=1063894193418&categoryId=201538503
A7: 2026-07-06 | B7: 2026-07-06 15:13:35 | C7: 塞尔达传说：王国之泪 | D7: 卡带 | E7: 1062839489790 | F7: 任天堂Switch游戏《塞尔达传说：王国之泪》港版中文卡带， 全新未拆封，带原装盒，支持简体中文，插卡即玩。动作冒险类，单人游戏，喜欢探索和开放世界的玩家别错过！同城可自提。不议价，售出不退。 | G7: 255 | H7: 吉林百分百好评 | J7: https://www.goofish.com/item?id=1062839489790&categoryId=201538503
A8: 2026-07-06 | B8: 2026-07-06 15:13:35 | C8: 塞尔达传说：王国之泪 | D8: 卡带 | E8: 1065444324578 | F8: Nintendo Switch 塞尔达传说：王国之泪 美版卡 带，带原包装盒，正版实体卡，插卡即玩，支持所有Switch主机（国行/港版/日版/欧美版都能用），动作冒险类，玩法自由，探索创造，amiibo兼容，聚会、朋友、家庭都适合，塞尔达系列粉丝必入～卡带和盒子保存很好，轻微划痕磨损，读卡正常，到手即玩！包邮，可自提，喜欢直接拍或私聊细节图～分类：Switch游戏卡带成色：轻微划痕磨损带原包装盒 | G8: 245 | H8: 北京回复超快 | J8: https://www.goofish.com/item?id=1065444324578&categoryId=201538503
A9: 2026-07-06 | B9: 2026-07-06 15:13:35 | C9: 塞尔达传说：王国之泪 | D9: 卡带 | E9: 1062527995032 | F9: Switch 塞尔达传说 王国之泪 中文插卡即玩，支持中文， 画面精美，动作冒险经典，喜欢塞尔达的朋友别错过。卡带保存很好，功能正常，成色实图所拍，看准再下单，售出不退不换。非偏远地区包邮，偏远地区补差5元，售后需要提供完整开箱视频 | G9: 222 | H9: 广东卖家信用极好 | J9: https://www.goofish.com/item?id=1062527995032&categoryId=201538503
A10: 2026-07-06 | B10: 2026-07-06 15:13:35 | C10: 塞尔达传说：王国之泪 | D10: 卡带 | E10: 1063229422642 | F10: 全新《塞尔达传说：王国之泪》港版中文卡带，带原装盒，插卡即玩 ，支持所有Switch主机，简体中文界面，动作冒险经典，剧情画质都很棒，喜欢塞尔达系列的朋友别错过！插拔次数很少，卡带表面很新没划痕，保存很好，功能正常，读取没问题，正版实体卡带，放心入！ | G10: 235 | H10: 吉林百分百好评 | J10: https://www.goofish.com/item?id=1063229422642&categoryId=201538503
A11: 2026-07-06 | B11: 2026-07-06 15:13:35 | C11: 塞尔达传说：王国之泪 | D11: 卡带 | E11: 1063921948905 | F11: 几乎全新 塞尔达传说 王国之泪 港版中文卡带 带原装盒，卡带保存很好，插拔次数很少，读卡正常，插卡即玩，支持所有Switch主机，动作冒险类，剧情画面都很棒，喜欢塞尔达的别错过～包邮发货，支持同城自提，价格可聊喜欢直接拍，细节随时问我！ | G11: 238 | H11: 江苏 | J11: https://www.goofish.com/item?id=1063921948905&categoryId=201538503
A12: 2026-07-06 | B12: 2026-07-06 15:13:35 | C12: 塞尔达传说：王国之泪 | D12: 卡带 | E12: 1063286182025 | F12: 全新未拆Switch 塞尔达传说王国之泪 港版中文实体卡带 带原包装盒 支持中文 插卡即玩南京发货 包邮 售出不退不换 | G12: 259 | H12: 江苏卖家信用极好 | J12: https://www.goofish.com/item?id=1063286182025&categoryId=201538503
A13: 2026-07-06 | B13: 2026-07-06 15:13:35 | C13: 塞尔达传说：王国之泪 | D13: 卡带 | E13: 1063322705883 | F13: 塞尔达传说王国之泪港版中文卡带任天堂Switch游戏《塞尔达 传说：王国之泪》港版中文实体卡带，带原装盒，卡带外观干净，插卡即玩，支持所有Switch主机。 | G13: 224 | H13: 上海百分百好评 | J13: https://www.goofish.com/item?id=1063322705883&categoryId=201538503
A14: 2026-07-06 | B14: 2026-07-06 15:13:35 | C14: 塞尔达传说：王国之泪 | D14: 卡带 | E14: 1062562059766 | F14: 全新Switch塞尔达传说:王国之泪，港版中文，首发版全新未 拆封，包含特典钥匙包。包邮，不议价，议价不回。 | G14: 255 | H14: 湖北百分百好评 | J14: https://www.goofish.com/item?id=1062562059766&categoryId=201538503
A15: 2026-07-06 | B15: 2026-07-06 15:13:35 | C15: 塞尔达传说：王国之泪 | D15: 卡带 | E15: 1063131326714 | F15: 塞尔达传说 王国之泪 Switch卡带支持中文 带原装盒 成色几乎全新 外观很新 没啥痕迹插拔次数少 卡带干净 | G15: 220 | H15: 河北卖家信用极好 | J15: https://www.goofish.com/item?id=1063131326714&categoryId=201538503
A16: 2026-07-06 | B16: 2026-07-06 15:13:35 | C16: 塞尔达传说：王国之泪 | D16: 卡带 | E16: 1064962448011 | F16: 塞尔达王国之泪 港版中文卡带，带原装盒，成色几乎全新，插卡即 玩，支持所有Switch主机，简体中文，动作冒险经典，剧情画面都很棒，适合自用或收藏，包邮杭州临平附近可自提，喜欢直接拍，细节私聊 | G16: 240 | H16: 浙江 | J16: https://www.goofish.com/item?id=1064962448011&categoryId=201538503
A17: 2026-07-06 | B17: 2026-07-06 15:13:35 | C17: 塞尔达传说：王国之泪 | D17: 卡带 | E17: 1062890417077 | F17: 全新《塞尔达传说：王国之泪》港版中文卡带，带原装盒，插卡即玩 ，支持所有Switch主机，简体中文界面，动作冒险经典，剧情画质都很棒，喜欢塞尔达系列的朋友别错过！插拔次数很少，卡带表面很新没划痕，保存很好，功能正常，读取没问题，正版实体卡带，放心入！同城可自提，喜欢直接拍，细节图私聊发～ | G17: 235 | H17: 吉林百分百好评 | J17: https://www.goofish.com/item?id=1062890417077&categoryId=201538503
A18: 2026-07-06 | B18: 2026-07-06 15:13:35 | C18: 塞尔达传说：王国之泪 | D18: 卡带 | E18: 1063118754379 | F18: switch塞尔达传说 王国之泪 中文卡带，插卡即玩，支持所 有Switch主机，日版也能用。卡带保存很好，盒子完整，功能正常，成色实图所拍，适合喜欢塞尔达系列和动作冒险游戏的朋友收藏或自用。二手卡带，功能正常，成色实图所拍，看准再下单，售出不退不换。非偏远地区包邮，偏远地区补差5元，售后需要提供完整开箱视频 | G18: 222 | H18: 广东卖家信用极好 | J18: https://www.goofish.com/item?id=1063118754379&categoryId=201538503
A19: 2026-07-06 | B19: 2026-07-06 15:13:35 | C19: 塞尔达传说：王国之泪 | D19: 卡带 | E19: 1064252533658 | F19: switch塞尔达ns王国之泪1.1.1版本 联机更新 非数 字版 非实体版 是正版！正版更新内容。但凡用高版本进过游戏都得格式化主机。 | H19: 广东百分百好评 | J19: https://www.goofish.com/item?id=1064252533658&categoryId=201538503
A20: 2026-07-06 | B20: 2026-07-06 15:13:35 | C20: 塞尔达传说：王国之泪 | D20: 卡带 | E20: 1064321009143 | F20: 《塞尔达传说 王国之泪》 switch 实体卡带回血 港版中文，成色很好，买来一直吃灰，真正的一手货（当时实体店买的全新的），带原装盒，盒子完整，喜欢直接拍二手物品售出不接受退货不刀，免开尊口爽快包顺丰 | G20: 225 | H20: 陕西百分百好评 | J20: https://www.goofish.com/item?id=1064321009143&categoryId=201538503
A21: 2026-07-06 | B21: 2026-07-06 15:13:35 | C21: 塞尔达传说：王国之泪 | D21: 卡带 | E21: 1062322094291 | F21: 塞尔达 繁体中文卡带 标准版 23年5月淘宝买的，原价三百多，没怎么玩，卡带保存不错，盒子也在默认顺丰到付 售出不退 | G21: 234 | H21: 广东发货极快 | J21: https://www.goofish.com/item?id=1062322094291&categoryId=201538503
A22: 2026-07-06 | B22: 2026-07-06 15:13:35 | C22: 塞尔达传说：王国之泪 | D22: 卡带 | E22: 1065422204334 | F22: 【出】任天堂switch1&2实体游戏卡带（塞尔达传说：旷野 之息、塞尔达传说：王国之泪、空洞骑士、宝可梦朱紫、宝可梦传说：阿尔宙斯、宝可梦传说：ZA）日版港版卡带，带原装盒（部分包含宣传卡），保存很好，插上就能玩，支持中文，动作冒险经典，收藏自用都合适。*包邮出，全程录像打包发货（收货售出后不退不换）需要可以联系私聊～一次多买打包更优惠 | G22: 240 | H22: 河南百分百好评 | J22: https://www.goofish.com/item?id=1065422204334&categoryId=201538503
A23: 2026-07-06 | B23: 2026-07-06 15:14:09 | C23: 塞尔达传说：旷野之息 | D23: 卡带 | E23: 1065071636384 | F23: Switch 塞尔达传说 王国之泪 中文卡带，插卡即玩，支持 中文，画面精美，玩法丰富，动作冒险经典，喜欢塞尔达的朋友别错过。卡带保存很好，功能正常，成色实图所拍，看准再下单，售出不退不换。非偏远地区包邮，偏远地区补差5元，售后需要提供完整开箱视频 | G23: 222 | H23: 广东卖家信用极好 | J23: https://www.goofish.com/item?id=1065071636384&categoryId=201538503
A24: 2026-07-06 | B24: 2026-07-06 15:14:09 | C24: 塞尔达传说：旷野之息 | D24: 卡带 | E24: 1062116315282 | F24: 任天堂Switch游戏卡带 塞尔达旷野之息 美版 几乎全新 带原装盒 支持中文界面 读卡正常 适合所有Switch主机 爽快包邮 | G24: 219 | H24: 广东 | J24: https://www.goofish.com/item?id=1062116315282&categoryId=201538503
A25: 2026-07-06 | B25: 2026-07-06 15:14:09 | C25: 塞尔达传说：旷野之息 | D25: 卡带 | E25: 1065061792450 | F25: Switch《塞尔达传说：旷野之息》卡带，带原装盒，美版，支 持中文，插拔次数少，卡带金手指状态好，盘面干净无划痕，盒子保存很好，适合所有Switch主机包邮！售出不退！ | G25: 215 | H25: 北京百分百好评 | J25: https://www.goofish.com/item?id=1065061792450&categoryId=201538503
A26: 2026-07-06 | B26: 2026-07-06 15:14:09 | C26: 塞尔达传说：旷野之息 | D26: 卡带 | E26: 1062696219271 | F26: 塞尔达传说旷野之息Switch卡带 美版实体卡带，支持中文，带原装盒，功能正常，适用于所有Switch主机（国行除外） | G26: 230 | H26: 湖北发货极快 | J26: https://www.goofish.com/item?id=1062696219271&categoryId=201538503
A27: 2026-07-06 | B27: 2026-07-06 15:14:09 | C27: 塞尔达传说：旷野之息 | D27: 卡带 | E27: 1063504494143 | F27: 塞尔达传说 呼吸之野 王者天下之泪 Switc 日本代购 塞尔达传说 呼吸之野 王者天下之泪 Switch【商品信息】已确认通电正常、各项功能可正常使用塞尔达传说旷野之息旷野之息（简称）王国之泪蒂亚金Nintendo Switch柔软实体版夏日开场礼上线啦！7.2-7.7 限时9折拍下后自动改价，等待改价成功后再付款哦由于海关备案规则调整，二手衣物类商品（适用范围：包含上衣、裤装、裙装、外套、童装 | G27: 512 | H27: 广东回复超快 | J27: https://www.goofish.com/item?id=1063504494143&categoryId=201538503
A28: 2026-07-06 | B28: 2026-07-06 15:14:09 | C28: 塞尔达传说：旷野之息 | D28: 卡带 | E28: 1061056579226 | F28: Switch游戏卡带《潜水员戴夫》周年纪念版，日版中文，带原 装盒，全新未拆封，塑封还在，保存很新，插卡即玩，支持所有Switch主机，电视和掌机模式都能用，正版实体卡，内容完整，功能正常。【全新未拆封】日版 潜水员戴夫 周年纪念版 Switch卡带日版中文 支持Switch主机 插卡即玩正版实体卡 带原装盒 包装完整休闲冒险必备 收藏自用都合适包邮 支持自提售出不退不换喜欢直接拍 | G28: 147 | H28: 山西卖家信用极好 | J28: https://www.goofish.com/item?id=1061056579226&categoryId=201538503
A29: 2026-07-06 | B29: 2026-07-06 15:14:09 | C29: 塞尔达传说：旷野之息 | D29: 卡带 | E29: 1062536275614 | F29: 全新未拆 日版NS《哈迪斯 HADES》卡带 带原装盒 支持Switch主机 插卡即玩动作RPG神作 支持中文 收藏自用都合适标价包邮 喜欢直拍 细节私聊 | G29: 120 | H29: 广东卖家信用极好 | J29: https://www.goofish.com/item?id=1062536275614&categoryId=201538503
A30: 2026-07-06 | B30: 2026-07-06 15:14:09 | C30: 塞尔达传说：旷野之息 | D30: 卡带 | E30: 1062527995032 | F30: Switch 塞尔达传说 王国之泪 中文插卡即玩，支持中文， 画面精美，动作冒险经典，喜欢塞尔达的朋友别错过。卡带保存很好，功能正常，成色实图所拍，看准再下单，售出不退不换。非偏远地区包邮，偏远地区补差5元，售后需要提供完整开箱视频 | G30: 222 | H30: 广东卖家信用极好 | J30: https://www.goofish.com/item?id=1062527995032&categoryId=201538503
A31: 2026-07-06 | B31: 2026-07-06 15:14:09 | C31: 塞尔达传说：旷野之息 | D31: 卡带 | E31: 1065444796068 | F31: 塞尔达传说 旷野之息 Switch 美版卡带，正版实体卡，插 卡即玩，支持中文，动作冒险类，开放世界玩法，朋友、家庭聚会都很适合，塞尔达粉必入～卡带成色轻微划痕磨损，金手指干净，读卡正常，到手即玩！包邮，可自提，喜欢直接拍或私聊细节图～分类：Switch游戏卡带成色：轻微划痕磨损美版卡带商品无质量问题，发出后不退不换。请拍摄完整开箱视频。 | G31: 229 | H31: 北京回复超快 | J31: https://www.goofish.com/item?id=1065444796068&categoryId=201538503
... A33: 2026-07-06 | B33: 2026-07-06 15:14:09 | C33: 塞尔达传说：旷野之息 | D33: 卡带 | E33: 1065023744561 | F33: Switch 塞尔达旷野之息 港版中文卡带，带原装盒子，插拔 次数只有一次，9.9新，买给人类小孩玩的说不喜欢就闲置了。原价297，现在230顺丰包邮。议价不回。支持所有Switch主机，国行可用，支持自提 | G33: 230 | H33: 福建百分百好评 | J33: https://www.goofish.com/item?id=1065023744561&categoryId=201538503
A34: 2026-07-06 | B34: 2026-07-06 15:14:09 | C34: 塞尔达传说：旷野之息 | D34: 卡带 | E34: 1063894193418 | F34: Switch OLED游戏机贴纸 普通版/续航版贴纸塞 尔达传说王国之泪UCG特典全新未拆封，原包装在包邮非偏远喜欢直接拍，细节私聊 | H34: 江苏百分百好评 | J34: https://www.goofish.com/item?id=1063894193418&categoryId=201538503
A35: 2026-07-06 | B35: 2026-07-06 15:14:09 | C35: 塞尔达传说：旷野之息 | D35: 卡带 | E35: 1063025990025 | F35: 任天堂switch 塞尔达传说 旷野之息 日版卡带 原装正品，带盒子，功能正常，插卡即玩支持所有Switch主机（日版/港版/国行都能用），开放世界动作冒险经典，画面很棒，适合喜欢塞尔达的玩家收藏或自用全国包邮，除偏远地区补运费不议价，喜欢直接拍，需要细节图可私聊NintendoSwitch 塞尔达旷野之息 | G35: 225 | H35: 浙江回复超快 | J35: https://www.goofish.com/item?id=1063025990025&categoryId=201538503
A36: 2026-07-06 | B36: 2026-07-06 15:14:09 | C36: 塞尔达传说：旷野之息 | D36: 卡带 | E36: 1062485279668 | F36: 几乎全新 塞尔达旷野之息 美版卡带 带原装盒 支持中文 读卡正常插上就能玩 经典神作 开放世界探索包邮 支持自提喜欢直接拍 细节私聊 | G36: 225 | H36: 天津卖家信用极好 | J36: https://www.goofish.com/item?id=1062485279668&categoryId=201538503
A37: 2026-07-06 | B37: 2026-07-06 15:14:09 | C37: 塞尔达传说：旷野之息 | D37: 卡带 | E37: 1062536483807 | F37: 全新未拆 Switch 路易吉鬼屋3 日版中文 标价包邮 喜欢直拍 细节私聊 | G37: 230 | H37: 广东卖家信用极好 | J37: https://www.goofish.com/item?id=1062536483807&categoryId=201538503
A38: 2026-07-06 | B38: 2026-07-06 15:14:09 | C38: 塞尔达传说：旷野之息 | D38: 卡带 | E38: 1061213159011 | F38: 塞尔达旷野之息日版卡带，带原装壳，成色如图，保存很好，读写正 常江浙沪包邮，喜欢直接拍，细节私聊 | G38: 228 | H38: 浙江百分百好评 | J38: https://www.goofish.com/item?id=1061213159011&categoryId=201538503
A39: 2026-07-06 | B39: 2026-07-06 15:14:09 | C39: 塞尔达传说：旷野之息 | D39: 卡带 | E39: 1063118754379 | F39: switch塞尔达传说 王国之泪 中文卡带，插卡即玩，支持所 有Switch主机，日版也能用。卡带保存很好，盒子完整，功能正常，成色实图所拍，适合喜欢塞尔达系列和动作冒险游戏的朋友收藏或自用。二手卡带，功能正常，成色实图所拍，看准再下单，售出不退不换。非偏远地区包邮，偏远地区补差5元，售后需要提供完整开箱视频 | G39: 222 | H39: 广东卖家信用极好 | J39: https://www.goofish.com/item?id=1063118754379&categoryId=201538503
A40: 2026-07-06 | B40: 2026-07-06 15:14:09 | C40: 塞尔达传说：旷野之息 | D40: 卡带 | E40: 1064497929138 | F40: 塞尔达传说旷野之息Switch卡带 任天堂Switch游戏《塞尔达传说：旷野之息》实体卡带，带原装盒，支持中文，插卡即玩。卡带外观干净，金手指无明显氧化，盒子封面完整，整体保存较好。 | G40: 235 | H40: 上海卖家信用优秀 | J40: https://www.goofish.com/item?id=1064497929138&categoryId=201538503
A41: 2026-07-06 | B41: 2026-07-06 15:14:09 | C41: 塞尔达传说：旷野之息 | D41: 卡带 | E41: 1063782517793 | F41: ⭕switch卡带 塞尔达旷野之息裸卡 ⭕任天堂正版，无盒，有中文⭕状态看图吧，标价包邮非偏远⭕喜欢直接拍，售出不退不换需要细节私聊，价格可聊 | G41: 231 | H41: 四川百分百好评 | J41: https://www.goofish.com/item?id=1063782517793&categoryId=201538503
...

Sheet 价格统计
A1: 游戏名 | B1: 版本 | C1: 最低价 | D1: 最高价 | E1: 平均价 | F1: 记录数 | G1: 最近抓取日期
A2: 塞尔达传说：王国之泪 | B2: 卡带 | C2: =MINIFS(价格历史!G:G,价格历史!C:C,A2) | D2: =MAXIFS(价格历史!G:G,价格历史!C:C,A2) | E2: =AVERAGEIF(价格历史!C:C,A2,价格历史!G:G) | F2: =COUNTIF(价格历史!C:C,A2) | G2: =MAXIFS(价格历史!A:A,价格历史!C:C,A2)
A3: 塞尔达传说：旷野之息 | B3: 卡带 | C3: =MINIFS(价格历史!G:G,价格历史!C:C,A3) | D3: =MAXIFS(价格历史!G:G,价格历史!C:C,A3) | E3: =AVERAGEIF(价格历史!C:C,A3,价格历史!G:G) | F3: =COUNTIF(价格历史!C:C,A3) | G3: =MAXIFS(价格历史!A:A,价格历史!C:C,A3)
A4: 马力欧卡丁车8豪华版 | B4: 卡带 | C4: =MINIFS(价格历史!G:G,价格历史!C:C,A4) | D4: =MAXIFS(价格历史!G:G,价格历史!C:C,A4) | E4: =AVERAGEIF(价格历史!C:C,A4,价格历史!G:G) | F4: =COUNTIF(价格历史!C:C,A4) | G4: =MAXIFS(价格历史!A:A,价格历史!C:C,A4)
A5: 超级马力欧奥德赛 | B5: 卡带 | C5: =MINIFS(价格历史!G:G,价格历史!C:C,A5) | D5: =MAXIFS(价格历史!G:G,价格历史!C:C,A5) | E5: =AVERAGEIF(价格历史!C:C,A5,价格历史!G:G) | F5: =COUNTIF(价格历史!C:C,A5) | G5: =MAXIFS(价格历史!A:A,价格历史!C:C,A5)
A6: 集合啦！动物森友会 | B6: 卡带 | C6: =MINIFS(价格历史!G:G,价格历史!C:C,A6) | D6: =MAXIFS(价格历史!G:G,价格历史!C:C,A6) | E6: =AVERAGEIF(价格历史!C:C,A6,价格历史!G:G) | F6: =COUNTIF(价格历史!C:C,A6) | G6: =MAXIFS(价格历史!A:A,价格历史!C:C,A6)
A7: 任天堂明星大乱斗 特别版 | B7: 卡带 | C7: =MINIFS(价格历史!G:G,价格历史!C:C,A7) | D7: =MAXIFS(价格历史!G:G,价格历史!C:C,A7) | E7: =AVERAGEIF(价格历史!C:C,A7,价格历史!G:G) | F7: =COUNTIF(价格历史!C:C,A7) | G7: =MAXIFS(价格历史!A:A,价格历史!C:C,A7)
A8: 宝可梦 朱 | B8: 卡带 | C8: =MINIFS(价格历史!G:G,价格历史!C:C,A8) | D8: =MAXIFS(价格历史!G:G,价格历史!C:C,A8) | E8: =AVERAGEIF(价格历史!C:C,A8,价格历史!G:G) | F8: =COUNTIF(价格历史!C:C,A8) | G8: =MAXIFS(价格历史!A:A,价格历史!C:C,A8)
A9: 宝可梦 紫 | B9: 卡带 | C9: =MINIFS(价格历史!G:G,价格历史!C:C,A9) | D9: =MAXIFS(价格历史!G:G,价格历史!C:C,A9) | E9: =AVERAGEIF(价格历史!C:C,A9,价格历史!G:G) | F9: =COUNTIF(价格历史!C:C,A9) | G9: =MAXIFS(价格历史!A:A,价格历史!C:C,A9)
A10: 宝可梦 剑 | B10: 卡带 | C10: =MINIFS(价格历史!G:G,价格历史!C:C,A10) | D10: =MAXIFS(价格历史!G:G,价格历史!C:C,A10) | E10: =AVERAGEIF(价格历史!C:C,A10,价格历史!G:G) | F10: =COUNTIF(价格历史!C:C,A10) | G10: =MAXIFS(价格历史!A:A,价格历史!C:C,A10)
A11: 宝可梦 盾 | B11: 卡带 | C11: =MINIFS(价格历史!G:G,价格历史!C:C,A11) | D11: =MAXIFS(价格历史!G:G,价格历史!C:C,A11) | E11: =AVERAGEIF(价格历史!C:C,A11,价格历史!G:G) | F11: =COUNTIF(价格历史!C:C,A11) | G11: =MAXIFS(价格历史!A:A,价格历史!C:C,A11)
A12: 异度神剑3 | B12: 卡带 | C12: =MINIFS(价格历史!G:G,价格历史!C:C,A12) | D12: =MAXIFS(价格历史!G:G,价格历史!C:C,A12) | E12: =AVERAGEIF(价格历史!C:C,A12,价格历史!G:G) | F12: =COUNTIF(价格历史!C:C,A12) | G12: =MAXIFS(价格历史!A:A,价格历史!C:C,A12)
A13: 异度神剑2 | B13: 卡带 | C13: =MINIFS(价格历史!G:G,价格历史!C:C,A13) | D13: =MAXIFS(价格历史!G:G,价格历史!C:C,A13) | E13: =AVERAGEIF(价格历史!C:C,A13,价格历史!G:G) | F13: =COUNTIF(价格历史!C:C,A13) | G13: =MAXIFS(价格历史!A:A,价格历史!C:C,A13)
... A35: 口袋妖怪 宝可梦传说Z-A | B35: 卡带 | C35: =MINIFS(价格历史!G:G,价格历史!C:C,A35) | D35: =MAXIFS(价格历史!G:G,价格历史!C:C,A35) | E35: =AVERAGEIF(价格历史!C:C,A35,价格历史!G:G) | F35: =COUNTIF(价格历史!C:C,A35) | G35: =MAXIFS(价格历史!A:A,价格历史!C:C,A35)

Sheet 游戏价格汇总
A1: 游戏名 | B1: 版本 | C1: 样本数 | D1: 参考价 | E1: 最低价 | F1: 最高价 | G1: 平均价 | H1: 抓取日期
A2: 任天堂明星大乱斗 特别版 | B2: 卡带 | C2: 185 | D2: 220 | E2: 64 | F2: 950 | G2: 226.79 | H2: 2026-07-06 21:05:26
A3: 塞尔达传说：旷野之息 | B3: 卡带 | C3: 149 | D3: 224 | E3: 50 | F3: 495 | G3: 213.33 | H3: 2026-07-06 21:05:26
A4: 塞尔达传说：王国之泪 | B4: 卡带 | C4: 142 | D4: 238 | E4: 55 | F4: 520 | G4: 247.44 | H4: 2026-07-06 21:05:26
A5: 宝可梦 剑 | B5: 卡带 | C5: 170 | D5: 197 | E5: 84 | F5: 800 | G5: 207.95 | H5: 2026-07-06 21:05:26
A6: 宝可梦 朱 | B6: 卡带 | C6: 170 | D6: 183 | E6: 60 | F6: 700 | G6: 208.76 | H6: 2026-07-06 21:05:26
A7: 宝可梦 盾 | B7: 卡带 | C7: 172 | D7: 179 | E7: 60 | F7: 999 | G7: 241.44 | H7: 2026-07-06 21:05:26
A8: 宝可梦 紫 | B8: 卡带 | C8: 162 | D8: 183 | E8: 60 | F8: 1010 | G8: 226.62 | H8: 2026-07-06 21:05:26
A9: 超级马力欧奥德赛 | B9: 卡带 | C9: 178 | D9: 235 | E9: 65 | F9: 833 | G9: 213.15 | H9: 2026-07-06 21:05:26
A10: 集合啦！动物森友会 | B10: 卡带 | C10: 165 | D10: 183 | E10: 50 | F10: 799 | G10: 207.86 | H10: 2026-07-06 21:05:26
A11: 马力欧卡丁车8豪华版 | B11: 卡带 | C11: 186 | D11: 206 | E11: 60 | F11: 550 | G11: 208.89 | H11: 2026-07-06 21:05:26
